<?xml version="1.0" encoding="utf-8"?>
<!-- This URDF was automatically created by SolidWorks to URDF Exporter! Originally created by Stephen Brawner (brawner@gmail.com) 
     Commit Version: 1.6.0-4-g7f85cfe  Build Version: 1.6.7995.38578
     For more information, please see http://wiki.ros.org/sw_urdf_exporter -->
<robot
  name="HoverRobot">
  <link
    name="base_link">
    <inertial>
      <origin
        xyz="0.00171515042148646 -0.00228933661043411 -0.0802327021083581"
        rpy="0 0 0" />
      <mass
        value="1.55020215164579" />
      <inertia
        ixx="0.00440413600234812"
        ixy="-1.68067952142844E-06"
        ixz="1.48418052374428E-05"
        iyy="0.00279549174608799"
        iyz="-8.57617612873675E-07"
        izz="0.00654484618482858" />
    </inertial>
    <visual>
      <origin
        xyz="0 0 0"
        rpy="0 0 0" />
      <geometry>
        <mesh
          filename="package://hoverrobot_description/meshes/base_link.STL" />
      </geometry>
      <material
        name="">
        <color
          rgba="0.792156862745098 0.819607843137255 0.933333333333333 1" />
      </material>
    </visual>
    <collision>
      <origin
        xyz="0 0 0"
        rpy="0 0 0" />
      <geometry>
        <mesh
          filename="package://hoverrobot_description/meshes/base_link.STL" />
      </geometry>
    </collision>
  </link>
  <link
    name="rueda_izquierda_link">
    <inertial>
      <origin
        xyz="1.2202E-06 4.4531E-06 0.08185"
        rpy="0 0 0" />
      <mass
        value="0.5" />
      <inertia
        ixx="0.0033197"
        ixy="-1.5836E-08"
        ixz="1.0219E-07"
        iyy="0.0033196"
        iyz="3.8047E-07"
        izz="0.0059555" />
    </inertial>
    <visual>
      <origin
        xyz="0 0 0"
        rpy="0 0 0" />
      <geometry>
        <mesh
          filename="package://hoverrobot_description/meshes/rueda_izquierda_link.STL" />
      </geometry>
      <material
        name="">
        <color
          rgba="0.95294 0.95294 0.95294 1" />
      </material>
    </visual>
    <collision>
      <origin
        xyz="0 0 0"
        rpy="0 0 0" />
      <geometry>
        <mesh
          filename="package://hoverrobot_description/meshes/rueda_izquierda_link.STL" />
      </geometry>
    </collision>
  </link>
  <joint
    name="rueda_izquierda_joint"
    type="continuous">
    <origin
      xyz="0.0067993 0.0785 -0.28423"
      rpy="-1.5708 0 0" />
    <parent
      link="base_link" />
    <child
      link="rueda_izquierda_link" />
    <axis
      xyz="0 0 1" />
    <limit
      effort="100"
      velocity="100" />
    <dynamics
      damping="0.1"
      friction="0.1" />
  </joint>
  <link
    name="rueda_derecha_link">
    <inertial>
      <origin
        xyz="0 0 0"
        rpy="0 0 0" />
      <mass
        value="0.5" />
      <inertia
        ixx="0.0033197"
        ixy="-1.5836E-08"
        ixz="1.0219E-07"
        iyy="0.0033196"
        iyz="3.8047E-07"
        izz="0.0059555" />
    </inertial>
    <visual>
      <origin
        xyz="0 0 0"
        rpy="0 0 0" />
      <geometry>
        <mesh
          filename="package://hoverrobot_description/meshes/rueda_derecha_link.STL" />
      </geometry>
      <material
        name="">
        <color
          rgba="1 1 1 1" />
      </material>
    </visual>
    <collision>
      <origin
        xyz="0 0 0"
        rpy="0 0 0" />
      <geometry>
        <mesh
          filename="package://hoverrobot_description/meshes/rueda_derecha_link.STL" />
      </geometry>
    </collision>
  </link>
  <joint
    name="rueda_derecha_joint"
    type="continuous">
    <origin
      xyz="0.0065514 -0.07825 -0.28427"
      rpy="-1.5708 0 0" />
    <parent
      link="base_link" />
    <child
      link="rueda_derecha_link" />
    <axis
      xyz="0 0 1" />
    <limit
      effort="100"
      velocity="100" />
    <dynamics
      damping="0.1"
      friction="0.1" />
  </joint>
</robot>